2025-01-04 10:52:04,310 - __main__ - INFO - Starting form processing
2025-01-04 10:52:04,311 - __main__ - INFO - Selecting AI model
2025-01-04 10:52:04,311 - __main__ - INFO - Starting model selection process
2025-01-04 10:52:04,312 - __main__ - INFO - Fetching available Ollama models
2025-01-04 10:52:04,315 - urllib3.connectionpool - DEBUG - Starting new HTTP connection (1): localhost:11434
2025-01-04 10:52:06,378 - urllib3.connectionpool - DEBUG - http://localhost:11434 "GET /api/tags HTTP/1.1" 200 None
2025-01-04 10:52:06,379 - __main__ - DEBUG - Found models: ['llama3.3:70b-instruct-q4_K_S', 'llama3.2-vision:latest', 'marco-o1:latest', 'phi3:latest', 'research-phi3:latest', 'phi3:14b-instruct', 'qwen2.5:latest', 'llama3.2:latest', 'NAME:latest', 'llava:13b', 'mxbai-embed-large:latest', 'nomic-embed-text:latest', 'x/llama3.2-vision:latest', 'mistral:latest', 'granite3-dense:latest']
2025-01-04 10:52:10,395 - __main__ - INFO - User selected default model (llama3.2:latest)
2025-01-04 10:52:10,396 - __main__ - INFO - Reading markdown file
2025-01-04 10:52:10,396 - __main__ - INFO - Attempting to read markdown file: day1form.md
2025-01-04 10:52:10,396 - __main__ - DEBUG - Successfully read 2133 characters from day1form.md
2025-01-04 10:52:10,396 - __main__ - INFO - Extracting fields from content
2025-01-04 10:52:10,397 - __main__ - INFO - Starting field extraction from markdown content
2025-01-04 10:52:10,397 - __main__ - DEBUG - Split content into 47 lines
2025-01-04 10:52:10,397 - __main__ - DEBUG - Found new field: Project Title
2025-01-04 10:52:10,397 - __main__ - DEBUG - Found new field: Concept Summary
2025-01-04 10:52:10,397 - __main__ - DEBUG - Found new field: Target Audience
2025-01-04 10:52:10,398 - __main__ - DEBUG - Found new field: Key Features
2025-01-04 10:52:10,398 - __main__ - DEBUG - Found new field: Technical Approach
2025-01-04 10:52:10,398 - __main__ - DEBUG - Found new field: Expected Challenges
2025-01-04 10:52:10,398 - __main__ - DEBUG - Found new field: Submission Format
2025-01-04 10:52:10,398 - __main__ - DEBUG - Found new field: Expected Outcome
2025-01-04 10:52:10,398 - __main__ - DEBUG - Found new field: Additional Notes (Optional)
2025-01-04 10:52:10,399 - __main__ - INFO - Successfully extracted 9 fields
2025-01-04 10:52:10,399 - __main__ - INFO - Generating questions
2025-01-04 10:52:10,399 - __main__ - INFO - Generating questions from fields
2025-01-04 10:52:10,399 - __main__ - DEBUG - Processing fields: ['Project Title', 'Concept Summary', 'Target Audience', 'Key Features', 'Technical Approach', 'Expected Challenges', 'Submission Format', 'Expected Outcome', 'Additional Notes (Optional)']
2025-01-04 10:52:10,400 - __main__ - INFO - Processing fields and getting user input
2025-01-04 10:52:19,996 - __main__ - INFO - Requesting suggestion from Ollama AI using model: llama3.2:latest
2025-01-04 10:52:19,996 - __main__ - DEBUG - Input answer: create AI solution assistant
2025-01-04 10:52:19,997 - __main__ - DEBUG - Sending POST request to Ollama API
2025-01-04 10:52:19,998 - urllib3.connectionpool - DEBUG - Starting new HTTP connection (1): localhost:11434
2025-01-04 10:52:46,283 - urllib3.connectionpool - DEBUG - http://localhost:11434 "POST /api/generate HTTP/1.1" 200 None
2025-01-04 10:52:57,656 - __main__ - ERROR - Unexpected error while getting Ollama suggestion: Extra data: line 2 column 1 (char 103)
2025-01-04 10:52:57,700 - __main__ - ERROR - Stack trace: Traceback (most recent call last):
  File "C:\Users\denni\AppData\Roaming\Python\Python312\site-packages\requests\models.py", line 963, in json
    return complexjson.loads(self.content.decode(encoding), **kwargs)
           ^^^^^^^^^^^^^^^^^^^^^^^^^^^^^^^^^^^^^^^^^^^^^^^^^^^^^^^^^^
  File "C:\Python312\Lib\json\__init__.py", line 346, in loads
    return _default_decoder.decode(s)
           ^^^^^^^^^^^^^^^^^^^^^^^^^^
  File "C:\Python312\Lib\json\decoder.py", line 341, in decode
    raise JSONDecodeError("Extra data", s, end)
json.decoder.JSONDecodeError: Extra data: line 2 column 1 (char 103)

During handling of the above exception, another exception occurred:

Traceback (most recent call last):
  File "C:\Users\denni\Documents\DDS_hackathon_2025JAN_AI_challenge\process_form.py", line 195, in get_ollama_suggestion
    suggestion = response.json()['response']
                 ^^^^^^^^^^^^^^^
  File "C:\Users\denni\AppData\Roaming\Python\Python312\site-packages\requests\models.py", line 971, in json
    raise RequestsJSONDecodeError(e.msg, e.doc, e.pos)
requests.exceptions.JSONDecodeError: Extra data: line 2 column 1 (char 103)

2025-01-04 10:53:45,683 - __main__ - INFO - Requesting suggestion from Ollama AI using model: llama3.2:latest
2025-01-04 10:53:45,683 - __main__ - DEBUG - Input answer: helps users avoid pro con dilemma and helps users create probability scenarios
2025-01-04 10:53:45,683 - __main__ - DEBUG - Sending POST request to Ollama API
2025-01-04 10:53:45,684 - urllib3.connectionpool - DEBUG - Starting new HTTP connection (1): localhost:11434
2025-01-04 10:53:48,152 - urllib3.connectionpool - DEBUG - http://localhost:11434 "POST /api/generate HTTP/1.1" 200 None
2025-01-04 10:53:53,913 - __main__ - ERROR - Unexpected error while getting Ollama suggestion: Extra data: line 2 column 1 (char 103)
2025-01-04 10:53:53,915 - __main__ - ERROR - Stack trace: Traceback (most recent call last):
  File "C:\Users\denni\AppData\Roaming\Python\Python312\site-packages\requests\models.py", line 963, in json
    return complexjson.loads(self.content.decode(encoding), **kwargs)
           ^^^^^^^^^^^^^^^^^^^^^^^^^^^^^^^^^^^^^^^^^^^^^^^^^^^^^^^^^^
  File "C:\Python312\Lib\json\__init__.py", line 346, in loads
    return _default_decoder.decode(s)
           ^^^^^^^^^^^^^^^^^^^^^^^^^^
  File "C:\Python312\Lib\json\decoder.py", line 341, in decode
    raise JSONDecodeError("Extra data", s, end)
json.decoder.JSONDecodeError: Extra data: line 2 column 1 (char 103)

During handling of the above exception, another exception occurred:

Traceback (most recent call last):
  File "C:\Users\denni\Documents\DDS_hackathon_2025JAN_AI_challenge\process_form.py", line 195, in get_ollama_suggestion
    suggestion = response.json()['response']
                 ^^^^^^^^^^^^^^^
  File "C:\Users\denni\AppData\Roaming\Python\Python312\site-packages\requests\models.py", line 971, in json
    raise RequestsJSONDecodeError(e.msg, e.doc, e.pos)
requests.exceptions.JSONDecodeError: Extra data: line 2 column 1 (char 103)

2025-01-04 10:53:59,068 - __main__ - INFO - Requesting suggestion from Ollama AI using model: llama3.2:latest
2025-01-04 10:53:59,068 - __main__ - DEBUG - Input answer: me
2025-01-04 10:53:59,068 - __main__ - DEBUG - Sending POST request to Ollama API
2025-01-04 10:53:59,069 - urllib3.connectionpool - DEBUG - Starting new HTTP connection (1): localhost:11434
2025-01-04 10:54:01,581 - urllib3.connectionpool - DEBUG - http://localhost:11434 "POST /api/generate HTTP/1.1" 200 None
2025-01-04 10:54:04,366 - __main__ - ERROR - Unexpected error while getting Ollama suggestion: Extra data: line 2 column 1 (char 102)
2025-01-04 10:54:04,366 - __main__ - ERROR - Stack trace: Traceback (most recent call last):
  File "C:\Users\denni\AppData\Roaming\Python\Python312\site-packages\requests\models.py", line 963, in json
    return complexjson.loads(self.content.decode(encoding), **kwargs)
           ^^^^^^^^^^^^^^^^^^^^^^^^^^^^^^^^^^^^^^^^^^^^^^^^^^^^^^^^^^
  File "C:\Python312\Lib\json\__init__.py", line 346, in loads
    return _default_decoder.decode(s)
           ^^^^^^^^^^^^^^^^^^^^^^^^^^
  File "C:\Python312\Lib\json\decoder.py", line 341, in decode
    raise JSONDecodeError("Extra data", s, end)
json.decoder.JSONDecodeError: Extra data: line 2 column 1 (char 102)

During handling of the above exception, another exception occurred:

Traceback (most recent call last):
  File "C:\Users\denni\Documents\DDS_hackathon_2025JAN_AI_challenge\process_form.py", line 195, in get_ollama_suggestion
    suggestion = response.json()['response']
                 ^^^^^^^^^^^^^^^
  File "C:\Users\denni\AppData\Roaming\Python\Python312\site-packages\requests\models.py", line 971, in json
    raise RequestsJSONDecodeError(e.msg, e.doc, e.pos)
requests.exceptions.JSONDecodeError: Extra data: line 2 column 1 (char 102)

2025-01-04 10:54:13,612 - __main__ - INFO - Requesting suggestion from Ollama AI using model: llama3.2:latest
2025-01-04 10:54:13,612 - __main__ - DEBUG - Input answer: python
2025-01-04 10:54:13,613 - __main__ - DEBUG - Sending POST request to Ollama API
2025-01-04 10:54:13,613 - urllib3.connectionpool - DEBUG - Starting new HTTP connection (1): localhost:11434
2025-01-04 10:54:16,053 - urllib3.connectionpool - DEBUG - http://localhost:11434 "POST /api/generate HTTP/1.1" 200 None
2025-01-04 10:54:22,568 - __main__ - ERROR - Unexpected error while getting Ollama suggestion: Extra data: line 2 column 1 (char 107)
2025-01-04 10:54:22,569 - __main__ - ERROR - Stack trace: Traceback (most recent call last):
  File "C:\Users\denni\AppData\Roaming\Python\Python312\site-packages\requests\models.py", line 963, in json
    return complexjson.loads(self.content.decode(encoding), **kwargs)
           ^^^^^^^^^^^^^^^^^^^^^^^^^^^^^^^^^^^^^^^^^^^^^^^^^^^^^^^^^^
  File "C:\Python312\Lib\json\__init__.py", line 346, in loads
    return _default_decoder.decode(s)
           ^^^^^^^^^^^^^^^^^^^^^^^^^^
  File "C:\Python312\Lib\json\decoder.py", line 341, in decode
    raise JSONDecodeError("Extra data", s, end)
json.decoder.JSONDecodeError: Extra data: line 2 column 1 (char 107)

During handling of the above exception, another exception occurred:

Traceback (most recent call last):
  File "C:\Users\denni\Documents\DDS_hackathon_2025JAN_AI_challenge\process_form.py", line 195, in get_ollama_suggestion
    suggestion = response.json()['response']
                 ^^^^^^^^^^^^^^^
  File "C:\Users\denni\AppData\Roaming\Python\Python312\site-packages\requests\models.py", line 971, in json
    raise RequestsJSONDecodeError(e.msg, e.doc, e.pos)
requests.exceptions.JSONDecodeError: Extra data: line 2 column 1 (char 107)

2025-01-04 10:54:29,805 - __main__ - INFO - Requesting suggestion from Ollama AI using model: llama3.2:latest
2025-01-04 10:54:29,805 - __main__ - DEBUG - Input answer: API requests
2025-01-04 10:54:29,805 - __main__ - DEBUG - Sending POST request to Ollama API
2025-01-04 10:54:29,806 - urllib3.connectionpool - DEBUG - Starting new HTTP connection (1): localhost:11434
2025-01-04 10:54:32,153 - urllib3.connectionpool - DEBUG - http://localhost:11434 "POST /api/generate HTTP/1.1" 200 None
2025-01-04 10:54:36,874 - __main__ - ERROR - Unexpected error while getting Ollama suggestion: Extra data: line 2 column 1 (char 103)
2025-01-04 10:54:36,875 - __main__ - ERROR - Stack trace: Traceback (most recent call last):
  File "C:\Users\denni\AppData\Roaming\Python\Python312\site-packages\requests\models.py", line 963, in json
    return complexjson.loads(self.content.decode(encoding), **kwargs)
           ^^^^^^^^^^^^^^^^^^^^^^^^^^^^^^^^^^^^^^^^^^^^^^^^^^^^^^^^^^
  File "C:\Python312\Lib\json\__init__.py", line 346, in loads
    return _default_decoder.decode(s)
           ^^^^^^^^^^^^^^^^^^^^^^^^^^
  File "C:\Python312\Lib\json\decoder.py", line 341, in decode
    raise JSONDecodeError("Extra data", s, end)
json.decoder.JSONDecodeError: Extra data: line 2 column 1 (char 103)

During handling of the above exception, another exception occurred:

Traceback (most recent call last):
  File "C:\Users\denni\Documents\DDS_hackathon_2025JAN_AI_challenge\process_form.py", line 195, in get_ollama_suggestion
    suggestion = response.json()['response']
                 ^^^^^^^^^^^^^^^
  File "C:\Users\denni\AppData\Roaming\Python\Python312\site-packages\requests\models.py", line 971, in json
    raise RequestsJSONDecodeError(e.msg, e.doc, e.pos)
requests.exceptions.JSONDecodeError: Extra data: line 2 column 1 (char 103)

2025-01-04 10:54:48,004 - __main__ - INFO - Requesting suggestion from Ollama AI using model: llama3.2:latest
2025-01-04 10:54:48,004 - __main__ - DEBUG - Input answer: python and githbu
2025-01-04 10:54:48,004 - __main__ - DEBUG - Sending POST request to Ollama API
2025-01-04 10:54:48,005 - urllib3.connectionpool - DEBUG - Starting new HTTP connection (1): localhost:11434
2025-01-04 10:54:50,451 - urllib3.connectionpool - DEBUG - http://localhost:11434 "POST /api/generate HTTP/1.1" 200 None
2025-01-04 10:54:54,477 - __main__ - ERROR - Unexpected error while getting Ollama suggestion: Extra data: line 2 column 1 (char 100)
2025-01-04 10:54:54,478 - __main__ - ERROR - Stack trace: Traceback (most recent call last):
  File "C:\Users\denni\AppData\Roaming\Python\Python312\site-packages\requests\models.py", line 963, in json
    return complexjson.loads(self.content.decode(encoding), **kwargs)
           ^^^^^^^^^^^^^^^^^^^^^^^^^^^^^^^^^^^^^^^^^^^^^^^^^^^^^^^^^^
  File "C:\Python312\Lib\json\__init__.py", line 346, in loads
    return _default_decoder.decode(s)
           ^^^^^^^^^^^^^^^^^^^^^^^^^^
  File "C:\Python312\Lib\json\decoder.py", line 341, in decode
    raise JSONDecodeError("Extra data", s, end)
json.decoder.JSONDecodeError: Extra data: line 2 column 1 (char 100)

During handling of the above exception, another exception occurred:

Traceback (most recent call last):
  File "C:\Users\denni\Documents\DDS_hackathon_2025JAN_AI_challenge\process_form.py", line 195, in get_ollama_suggestion
    suggestion = response.json()['response']
                 ^^^^^^^^^^^^^^^
  File "C:\Users\denni\AppData\Roaming\Python\Python312\site-packages\requests\models.py", line 971, in json
    raise RequestsJSONDecodeError(e.msg, e.doc, e.pos)
requests.exceptions.JSONDecodeError: Extra data: line 2 column 1 (char 100)

2025-01-04 10:54:58,539 - __main__ - INFO - Requesting suggestion from Ollama AI using model: llama3.2:latest
2025-01-04 10:54:58,539 - __main__ - DEBUG - Input answer: money
2025-01-04 10:54:58,539 - __main__ - DEBUG - Sending POST request to Ollama API
2025-01-04 10:54:58,540 - urllib3.connectionpool - DEBUG - Starting new HTTP connection (1): localhost:11434
2025-01-04 10:55:00,925 - urllib3.connectionpool - DEBUG - http://localhost:11434 "POST /api/generate HTTP/1.1" 200 None
2025-01-04 10:55:03,205 - __main__ - ERROR - Unexpected error while getting Ollama suggestion: Extra data: line 2 column 1 (char 106)
2025-01-04 10:55:03,206 - __main__ - ERROR - Stack trace: Traceback (most recent call last):
  File "C:\Users\denni\AppData\Roaming\Python\Python312\site-packages\requests\models.py", line 963, in json
    return complexjson.loads(self.content.decode(encoding), **kwargs)
           ^^^^^^^^^^^^^^^^^^^^^^^^^^^^^^^^^^^^^^^^^^^^^^^^^^^^^^^^^^
  File "C:\Python312\Lib\json\__init__.py", line 346, in loads
    return _default_decoder.decode(s)
           ^^^^^^^^^^^^^^^^^^^^^^^^^^
  File "C:\Python312\Lib\json\decoder.py", line 341, in decode
    raise JSONDecodeError("Extra data", s, end)
json.decoder.JSONDecodeError: Extra data: line 2 column 1 (char 106)

During handling of the above exception, another exception occurred:

Traceback (most recent call last):
  File "C:\Users\denni\Documents\DDS_hackathon_2025JAN_AI_challenge\process_form.py", line 195, in get_ollama_suggestion
    suggestion = response.json()['response']
                 ^^^^^^^^^^^^^^^
  File "C:\Users\denni\AppData\Roaming\Python\Python312\site-packages\requests\models.py", line 971, in json
    raise RequestsJSONDecodeError(e.msg, e.doc, e.pos)
requests.exceptions.JSONDecodeError: Extra data: line 2 column 1 (char 106)

2025-01-04 10:55:03,207 - __main__ - INFO - Saving results to JSON file
2025-01-04 10:55:03,208 - __main__ - INFO - Successfully saved results to day1form.json
